## 返回值与错误处理

Rust 中的错误主要分为两类：

- **可恢复错误**，通常用于从系统全局角度来看可以接受的错误，例如处理用户的访问、操作等错误，这些错误只会影响某个用户自身的操作进程，而不会对系统的全局稳定性产生影响；
- **不可恢复错误**，刚好相反，该错误通常是全局性或者系统性的错误，例如数组越界访问，系统启动时发生了影响启动流程的错误等等，这些错误的影响往往对于系统来说是致命的。

### panic! 与不可恢复错误

对于严重到影响程序运行的错误（不可恢复的错误），触发 `panic` 是很好的解决方式。在 Rust 中触发 `panic` 有两种方式：**被动触发和主动调用**；

### 被动触发

如数组越界操作。

### 主动调用

当调用执行`panic!` 宏时，**程序会打印出一个错误信息，展开报错点往前的函数调用堆栈，最后退出程序**。

## backtrace 栈展开

栈展开(也称栈回溯)，它包含了函数调用的顺序，当然按照逆序排列：最近调用的函数排在列表的最上方

使用 `RUST_BACKTRACE=1 cargo run` 或 `$env:RUST_BACKTRACE=1 ; cargo run` 来运行程序。

## panic 时的两种终止方式

当出现 `panic!` 时，程序提供了两种方式来处理终止流程：**栈展开**和**直接终止**。

默认的方式就是 `栈展开`，这意味着 Rust 会回溯栈上数据和函数调用，因此也意味着更多的善后工作，好处是可以给出充分的报错信息和栈调用信息，便于事后的问题复盘。`直接终止`，顾名思义，不清理数据就直接退出程序，善后工作交与操作系统来负责。

例如下面的配置修改 `Cargo.toml` 文件，实现在 `release `模式下遇到 `panic` 直接终止：

```rust
[profile.release]
panic = 'abort'
```

## 线程 panic 后，程序是否会终止？

长话短说，如果是 main 线程，则程序会终止，**如果是其它子线程，该线程会终止，但是不会影响 main 线程**。因此，尽量不要在 main 线程中做太多任务，将这些任务交由子线程去做，就算子线程 panic 也不会导致整个程序的结束。

## 何时该使用 panic!

当没有错误发生时，函数返回一个用 `Result` 类型包裹的值 `Ok(T)`，当错误时，返回一个 `Err(E)`。对于 `Result` 返回我们有很多处理方法，最简单粗暴的就是 `unwrap` 和 `expect`，这两个函数非常类似，我们以 `unwrap` 举例：

```rust
enum Result<T, E> {
    Ok(T),
    Err(E),
}
```

下面 `parse` 方法试图将字符串 `"127.0.0.1" `解析为一个 IP 地址类型 `IpAddr`，它返回一个 `Result<IpAddr, E>` 类型，如果解析成功，则把 `Ok(IpAddr)` 中的值赋给 `home`，如果失败，则不处理 `Err(E)`，而是直接 `panic`。

```rust
use std::net::IpAddr;
let home: IpAddr = "127.0.0.1".parse().unwrap();
```

成功则返回值，失败则 `panic`，总之不进行任何错误处理。

## 可恢复的错误 Result

一种更温和的错误处理方式：`Result<T, E>`。

```rust
use std::fs::File;

fn main() {
    let f = File::open("hello.txt");
    let f = match f {
        Ok(file) => file,
        Err(error) => {
            panic!("Problem opening the file: {:?}", error)
        },
    };
}
```

以上 `File::open` 返回一个 `Result` 类型。

## 对返回的错误进行处理

需要对部分错误进行特殊处理，而不是所有错误都直接崩溃：

```rust
let f = match f {
    Ok(file) => file,
    Err(error) => match error.kind() {
        ErrorKind::NotFound => match File::create("hello.txt") {
            Ok(fc) => fc,
            Err(e) => panic!("Problem creating the file: {:?}", e),
        },
        other_error => panic!("Problem opening the file: {:?}", other_error),
    },
};
```

## 失败就 panic: unwrap 和 expect

因为 `match` 的穷尽匹配特性，你总要去处理下 `Err` 分支。那么有没有办法简化这个过程？有，答案就是 `unwrap` 和 `expect`。

它们的作用就是，如果返回成功，就将 `Ok(T)` 中的值取出来，如果失败，就直接 `panic`，真的勇士绝不多 BB，**直接崩溃**。

```rust
use std::fs::File;

fn main() {
    let f = File::open("hello.txt").unwrap();
}
```

`expect` 跟 `unwrap` 很像，也是遇到错误直接 `panic`, 但是**会带上自定义的错误提示信息**，相当于重载了错误打印的函数：

```rust
use std::fs::File;

fn main() {
    let f = File::open("hello.txt").expect("Failed to open hello.txt");
}
```

## 传播错误

实际应用中，大概率会把错误层层上传然后交给调用链的上游函数进行处理，错误传播将极为常见。

```rust
let mut f = match f {
    // 打开文件成功，将file句柄赋值给f
    Ok(file) => file,
    // 打开文件失败，将错误返回(向上传播)
    Err(e) => return Err(e),
};
```

### 传播界的大明星：?

```rust
use std::fs::File;
use std::io;
use std::io::Read;

fn read_username_from_file() -> Result<String, io::Error> {
    let mut f = File::open("hello.txt")?;
    let mut s = String::new();
    f.read_to_string(&mut s)?;
    Ok(s)
}
```

 `?` 就是一个宏，它的作用跟上面的 `match` 几乎一模一样。

如果结果是 `Ok(T)`，则把 `T` 赋值给 `f`，如果结果是 `Err(E)`，则返回该错误，所以 `?` 特别适合用来传播错误。

```rust
fn open_file() -> Result<File, Box<dyn std::error::Error>> {
    let mut f = File::open("hello.txt")?;
    Ok(f)
}
```

上面代码中 `File::open` 报错时返回的错误是 `std::io::Error` 类型，但是 `open_file` 函数返回的错误类型是 `std::error::Error` 的特征对象，可以看到一个错误类型通过 `?` 返回后，变成了另一个错误类型，这就是 `?` 的神奇之处。

根本原因是在于标准库中定义的 `From` 特征，该特征有一个方法 `from`，用于把一个类型转成另外一个类型，`?` 可以自动调用该方法，然后进行隐式类型转换。因此只要函数返回的错误 `ReturnError` 实现了 `From<OtherError>` 特征，那么 `?` 就会自动把 `OtherError` 转换为 `ReturnError`。

```rust
fn read_username_from_file() -> Result<String, io::Error> {
    let mut s = String::new();

    File::open("hello.txt")?.read_to_string(&mut s)?;

    Ok(s)
}
```

 `?` 还能实现链式调用，`File::open` 遇到错误就返回，没有错误就将 `Ok` 中的值取出来用于下一个方法调用；

### ? 用于 Option 的返回

? 不仅仅可以用于 Result 的传播，还能用于 Option 的传播

`Result` 通过 `?` 返回错误，那么 `Option` 就通过 `?` 返回 `None`：

```rust
fn first(arr: &[i32]) -> Option<&i32> {
   let v = arr.get(0)?;
   Some(v)
}
```

初学者在用 `?` 时，老是会犯错，例如写出这样的代码：

```rust
fn first(arr: &[i32]) -> Option<&i32> {
   arr.get(0)?
}
```

这段代码无法通过编译，切记：`?` 操作符需要一个变量来承载正确的值，这个函数只会返回 `Some(&i32)` 或者 `None`，只有错误值能直接返回，正确的值不行。

因此 `?` 只能用于以下形式：

- `let v = xxx()?;`
- `xxx()?.yyy()?;`

#### 带返回值的 main 函数

```rust
use std::fs::File;

fn main() {
    let f = File::open("hello.txt")?;
}
```

因为 `?` 要求 `Result<T, E>` 形式的返回值，而 `main` 函数的返回是 `()`，因此无法满足，那是不是就无解了呢？

实际上 Rust 还支持另外一种形式的 `main` 函数：

```rust
use std::error::Error;
use std::fs::File;

fn main() -> Result<(), Box<dyn Error>> {
    let f = File::open("hello.txt")?;

    Ok(())
}
```

至于 main 函数可以有多种返回值，那是因为实现了 `std::process::Termination` 特征，目前为止该特征还没进入稳定版 Rust 中。

### try!

在 `?` 横空出世之前( Rust 1.13 )，Rust 开发者还可以使用 `try!` 来处理错误，该宏的大致定义如下：

```rust
macro_rules! try {
    ($e:expr) => (match $e {
        Ok(val) => val,
        Err(err) => return Err(::std::convert::From::from(err)),
    });
}
```

总之，`try!` 作为前浪已经死在了沙滩上。